
<mujoco model='ADROIT-watercup'>
    <default>
        <motor ctrllimited="true" ctrlrange="-1 1" gear="5"/>
        <default class="cup">
        <joint type="slide" damping="3" stiffness="20"/>
        <geom type="capsule" size=".008"/>
        </default>
    </default>

    <!-- ======= WORLD ======= -->
    <worldbody>
        <light directional='false' diffuse='.7 .7 .7' specular='0.03 0.03 0.03' pos='-1 -1.0 4.0' dir='1 1.0 -4'/>
        <geom name='ground' size="1.5 1.5 0.25" pos="0 0 -1" type="plane" contype="1" conaffinity="0" material="groundplane" />
        <camera name="fixed" pos="0 -0.7 0.7" quat="0.92388 0.382683 0 0" />
        <!-- Camera for the VIL paper -->
        <camera name="vil_camera" pos="0 -1.2 1.2" quat="0.92388 0.382683 0 0" />
 
        <!-- ======= TABLE ======= -->
        <body name="table">
            <!-- <geom size="0.5 0.5 0.025" type="plane" material="table2d" /> --> <!-- Plane has better contacts -->
            <geom size="0.45 0.45 0.025" pos="0 0 -0.025" type="box" material="tablecube" />
            <geom size="0.04 0.5" pos="0.4 0.4 -0.501" quat="0 1 0 0" type="cylinder" contype="0" conaffinity="0" />
            <geom size="0.04 0.5" pos="-0.4 0.4 -0.501" quat="0 1 0 0" type="cylinder" contype="0" conaffinity="0" />
            <geom size="0.04 0.5" pos="0.4 -0.4 -0.501" quat="0 1 0 0" type="cylinder" contype="0" conaffinity="0" />
            <geom size="0.04 0.5" pos="-0.4 -0.4 -0.501" quat="0 1 0 0" type="cylinder" contype="0" conaffinity="0" />
        </body>
        
        <!-- ======= MOCAP ======= -->
        <body name="vive_tracker" pos="0 -0.35 0.25" mocap="true">
            <inertial pos="0 0 0" mass="0.064" diaginertia="1.70667e-05 1.70667e-05 1.70667e-05" />
            <geom size="0.03 0.01" type="cylinder" contype="0" conaffinity="0" group="3" rgba="0.3 0.3 0.3 0.3" />
        </body>

        <!-- ======= HAND ======= -->
        <body name="forearm" pos="0.1 -0.7 0.5" euler="-1.57 0 -1.57">
            <inertial pos="0.001 -0.002 0.29" quat="0.982037 -0.0160006 0 -0.188007" mass="4" diaginertia="0.01 0.01 0.0075" />
            <joint name="ARTx" pos="0 0 0" axis="1 0 0" type="slide" range="-0.25 0.25" damping="20" />
            <joint name="ARTy" pos="0 0 0" axis="0 1 0" type="slide" range="0 0.2" damping="20" />
            <joint name="ARTz" pos="0 0 0" axis="0 0 1" type="slide" range="-0.3 0.5" damping="20" />
            <joint name="ARRx" pos="0 0 0" axis="1 0 0" range="-.75 .75" damping="20" />
            <joint name="ARRy" pos="0 0 0" axis="0 1 0" range="-.75 .75" damping="20" />
            <joint name="ARRz" pos="0 0 0" axis="0 0 1" range="-.75 .75" damping="20" />
            <geom name="V_forearm" class="D_Vizual" pos="0 -.01 .181" euler="0 0 -1.57"  mesh="forearm_simple" />
            <geom name="C_forearm1" class="DC_Hand" size="0.05 0.033" pos="0 0 0.29" type="capsule" rgba="0.4 0.5 0.6 0.1" />
            <!-- ======= Adroit ======= -->
            <include file="DAPG_Adroit.xml"/>
        </body>

        <!-- WATERCUP -->
        <!-- <body name="watercup" pos="0 0 0" -->
        <body name="cup" pos="0 0 .6" childclass="cup">
        <joint name="cup_x" axis="1 0 0"/>
        <joint name="cup_z" axis="0 0 1"/>
        <geom name="cup_part_0" fromto="-.05 0 0 -.05 0 -.075" />
        <geom name="cup_part_1" fromto="-.05 0 -.075 -.025 0 -.1" />
        <geom name="cup_part_2" fromto="-.025 0 -.1 .025 0 -.1" />
        <geom name="cup_part_3" fromto=".025 0 -.1 .05 0 -.075" />
        <geom name="cup_part_4" fromto=".05 0 -.075 .05 0 0" />
        <site name="cup" pos="0 0 -.108" size=".005"/>
        </body>
    </worldbody>
    
    <actuator>
        <general name="A_ARTx" joint="ARTx" ctrlrange="-0.25 0.25" biastype="affine" gainprm="500 0 0" biasprm="0 -200 0" />
        <general name="A_ARTy" joint="ARTy" ctrlrange="0.0 0.2" biastype="affine" gainprm="500 0 0" biasprm="0 -200 0" />
        <general name="A_ARTz" joint="ARTz" ctrlrange="-0.3 0.5" biastype="affine" gainprm="500 0 0" biasprm="0 -200 0" />
        <general name="A_ARRx" joint="ARRx" ctrlrange="-.75 .75" biastype="affine" gainprm="500 0 0" biasprm="0 -200 0" />
        <general name="A_ARRy" joint="ARRy" ctrlrange="-.75 .75" biastype="affine" gainprm="500 0 0" biasprm="0 -200 0" />
        <general name="A_ARRz" joint="ARRz" ctrlrange="-.75 .75" biastype="affine" gainprm="500 0 0" biasprm="0 -200 0" />
    </actuator>
       
    <include file='DAPG_assets.xml'/>
       
    
</mujoco>
